<!-- 添加一个自定义形状的机器人，主要有底盘和摄像头两部分组成 -->

<robot name="mycar">
    <!-- 1.底盘link -->
    <link name="base_link">
        <visual>
            <geometry>
                <box size="0.3 0.2 0.1"/>
            </geometry>
            <origin xyz="0 0 0" rpy="0 0 0"/>
            <material name="blue">
                <color rgba="0.5 0.5 0.5 0.5"/>
            </material>
        </visual>
    </link>

    <!-- 2.摄像头link --> 
    <link name="camera">
        <visual>
            <geometry>
                <box size="0.02 0.05 0.05" />
            </geometry>
            <origin xyz="0 0 0.025" rpy="0 0 0"/>
            <material name="yellow">
                <color rgba="1 0 0 0.5"/>
            </material>
        </visual>
    </link>

    <!-- 3.链接两个link的关节joint信息 -->
    <joint name="camera2base" type="continuous">
        <!-- 父 link -->
        <parent link="base_link" />
        <!-- 子 link -->
        <child link="camera" />
        <!-- 设置偏移量 -->
        <origin xyz="0.12 0 0.05" rpy="0 0 0" />
        <!-- 关节旋转的坐标轴 -->
        <axis xyz="0 0 1" />
    </joint>    

</robot>