<robot name="mycar">
    <!-- base_footpritn -->
    <link name="base_footprint">
        <visual>
            <geometry>
                <box size="0.001 0.001 0.001" />
            </geometry>
        </visual>
    </link>

    <!-- 1.底盘link -->
    <link name="car_base">
        <visual>
            <geometry>
                <box size="0.3 0.2 0.1"/>
            </geometry>
            <origin xyz="0 0 0" rpy="0 0 0"/>
            <material name="blue">
                <color rgba="0.5 0.5 0.5 0.5"/>
            </material>
        </visual>
    </link>

    <!-- 2.摄像头link --> 
    <link name="camera">
        <visual>
            <geometry>
                <box size="0.02 0.05 0.05" />
            </geometry>
            <origin xyz="0 0 0.025" rpy="0 0 0"/>
            <material name="yellow">
                <color rgba="1 0 0 0.5"/>
            </material>
        </visual>
    </link>

    <!-- 3.链接两个link的关节joint信息 -->
    <joint name="camera2base" type="continuous">
        <parent link="car_base" />
        <child link="camera" />
        <origin xyz="0.12 0 0.05" rpy="0 0 0" />
        <axis xyz="0 0 1" />
    </joint>    

    <!-- 添加base_joint -->
    <joint name="link2footprint" type="fixed" >
        <parent link="base_footprint" />
        <child link="car_base" />
        <origin xyz="0 0 0.05" rpy="0 0 0"/>
        <axis xyz="0 0 0" />
    </joint>

</robot>